Traceback (most recent call last):
  File "/Users/felix/miniconda3/envs/fin-bots/lib/python3.9/site-packages/nbclient/client.py", line 730, in _async_poll_for_reply
    msg = await ensure_async(self.kc.shell_channel.get_msg(timeout=new_timeout))
  File "/Users/felix/miniconda3/envs/fin-bots/lib/python3.9/site-packages/nbclient/util.py", line 96, in ensure_async
    result = await obj
  File "/Users/felix/miniconda3/envs/fin-bots/lib/python3.9/site-packages/jupyter_client/channels.py", line 230, in get_msg
    raise Empty
_queue.Empty

During handling of the above exception, another exception occurred:

Traceback (most recent call last):
  File "/Users/felix/miniconda3/envs/fin-bots/lib/python3.9/site-packages/jupyter_cache/executors/utils.py", line 51, in single_nb_execution
    executenb(
  File "/Users/felix/miniconda3/envs/fin-bots/lib/python3.9/site-packages/nbclient/client.py", line 1204, in execute
    return NotebookClient(nb=nb, resources=resources, km=km, **kwargs).execute()
  File "/Users/felix/miniconda3/envs/fin-bots/lib/python3.9/site-packages/nbclient/util.py", line 84, in wrapped
    return just_run(coro(*args, **kwargs))
  File "/Users/felix/miniconda3/envs/fin-bots/lib/python3.9/site-packages/nbclient/util.py", line 62, in just_run
    return loop.run_until_complete(coro)
  File "/Users/felix/miniconda3/envs/fin-bots/lib/python3.9/asyncio/base_events.py", line 647, in run_until_complete
    return future.result()
  File "/Users/felix/miniconda3/envs/fin-bots/lib/python3.9/site-packages/nbclient/client.py", line 663, in async_execute
    await self.async_execute_cell(
  File "/Users/felix/miniconda3/envs/fin-bots/lib/python3.9/site-packages/nbclient/client.py", line 949, in async_execute_cell
    exec_reply = await self.task_poll_for_reply
  File "/Users/felix/miniconda3/envs/fin-bots/lib/python3.9/site-packages/nbclient/client.py", line 754, in _async_poll_for_reply
    await self._async_handle_timeout(timeout, cell)
  File "/Users/felix/miniconda3/envs/fin-bots/lib/python3.9/site-packages/nbclient/client.py", line 801, in _async_handle_timeout
    raise CellTimeoutError.error_from_timeout_and_cell(
nbclient.exceptions.CellTimeoutError: A cell timed out while it was being executed, after 180 seconds.
The message was: Cell execution timed out.
Here is a preview of the cell contents:
-------------------
['fig,ax = plt.subplots(figsize=(6,6))', '', 'model_h0 = bind(run_random,buy_chance=buy_chance,short_chance=short_chance,hold_time=28)', 'model_h1 = bind(run_model,n_periods=28,threshold=0.08,hold_time=28)', '    ']
...
['title_r1 = f"h0 mean={np.array(h0).mean():.4f}\\n"', 'title_r2 = f"h1 value={x:.4f}"', '', 'ax.set_title(title_r1 + title_r2)', "ax.legend(loc ='upper left')"]
-------------------

